Workbook

Sheet 1안
A1: =CONCATENATE(B3,"_",D3,IF(ISBLANK(E3), "", ","),E3,IF(ISBLANK(F3), "", ","),F3,"_평가계획서(안)_",H3)
A2: * 정보입력 란
A3: 평가기관 : | B3: (주)베이스 | C3: 평가종류 : | D3: 정기검사 | G3: 완/미완 선택 : | H3: 미완
A4: 내부심사 : | B4: 권종국
A5: 컨설팅 : | B5: 김덕훈 | C5: 김덕훈
A6: 직전 평가반 : | B6: 이현자 | C6: 김상진 | D6: 김종상 | E6: 박병옥 | F6: 김기웅
A7: 평가일 :
A8: * 평가반 구성 안
A9: 역할 | B9: 회사/기관명 | C9: 성명 | D9: 연락처 | E9: 이메일 | F9: 중분류 | G9: 주소 | H9: 비고
A10: 평가반장
A11: 기술평가사
A12: 기술평가사
A13: 기관정보 | E13: 주소정보
A14: 담당자명 | B14: 성연석 | E14: 소재지 | F14: 충청남도 아산시 둔포면 윤보선로336번길 49
A15: 담당자연락처 | B15: 010-6346-0984 | E15: 소재지-1
A16: 담당자이메일 | B16: sung.ys@basscom.net | E16: 소재지-2
A18: 순번 | B18: 대분류 코드 | C18: 측정분야(대분류) | D18: 중분류 코드 | E18: 측정분야(중분류) | F18: 제품 및 물질 | G18: 제품 및 물질(영문) | H18: 분류 | I18: 규격코드 | J18: 규격명 | K18: 구성요소,특성(시험범위)(한글) | L18: 이력항목 | M18: 연도 | N18: 규격코드(영문) | O18: 규격명(영문) | P18: 구성요소,특성(시험범위)(영문) | Q18: 현장시험가능항목 | R18: 사업장구분
A19: 1 | B19: 01 | C19: 역학시험 | D19: 007 | E19: 유리와 유리제품 | F19: 유리와 유리제품 | G19: Glass and Related Products | H19: KS | I19: KS L ISO 7991:1987 | J19: 유리 - 평균 선형 열팽창 계수의 측정 | K19: (1.0 × 10⁻⁶ ~ 5.0 × 10⁻⁵) K⁻¹ | L19: 신규 | M19: 1987 | N19: KS L ISO 7991:1987 | O19: Glass - Determination of coefficient of mean linear thermal expansion | P19: (1.0 × 10⁻⁶ ~ 5.0 × 10⁻⁵) K⁻¹ | Q19: N | R19: 소재지
A20: 2 | B20: 01 | C20: 역학시험 | D20: 010 | E20: 플라스틱 및 관련제품 | F20: 플라스틱 및 관련제품 | G20: Plastics and Related Products | H20: KS | I20: KS M ISO 11358-1:2014 | J20: 플라스틱 — 고분자의 열중량 분석(TGA) -제1부: 일반 원칙 | K20: (25 ~ 1 000) ℃ | L20: 신규 | M20: 2014 | N20: KS M ISO 11358-1:2014 | O20: Plastics -Thermogravimetry (TG) of Polymers - Part 1: General principles | P20: (25 ~ 1 000) ℃ | Q20: N | R20: 소재지
A21: 3 | B21: 01 | C21: 역학시험 | D21: 010 | E21: 플라스틱 및 관련제품 | F21: 플라스틱 및 관련제품 | G21: Plastics and Related Products | H21: 기타 | I21: ASTM D3418-21 | J21: Standard Test Method for Transition Temperatures and Enthalpies of Fusion and Crystallization of Polymers by Differential Scanning Calorimetry | K21: (25 ~ 600) ℃ | L21: 신규 | M21: 2021 | N21: ASTM D3418-21 | O21: Standard Test Method for Transition Temperatures and Enthalpies of Fusion and Crystallization of Polymers by Differential Scanning Calorimetry | P21: (25 ~ 600) ℃ | Q21: N | R21: 소재지
A22: 4 | B22: 01 | C22: 역학시험 | D22: 010 | E22: 플라스틱 및 관련제품 | F22: 플라스틱 및 관련제품 | G22: Plastics and Related Products | H22: KS | I22: KS M ISO 11359-2:1999 | J22: 플라스틱 - 열기계 분석(TMA) -제 2부: 선열팽창계수 및 유리전이온도의 측정 | K22: (25 ~ 600) ℃ | L22: 신규 | M22: 1999 | N22: KS M ISO 11359-2:1999 | O22: Plastics-Thermomechanical analysis (TMA)-Part 2: Determination of coefficient of linear thermal expansion and glass transition temperature | P22: (25 ~ 600) ℃ | Q22: N | R22: 소재지
A23: 5 | B23: 02 | C23: 화학시험 | D23: 025 | E23: 실내 및 기타환경 | F23: 실내 및 기타환경 | G23: Indoor and other environments | H23: KS | I23: KS C IEC 62321-3-1:2013 | J23: 전기전자 제품에서 특정물질의 정량 - 제3-1부 : X선 형광 분석법에 의한 납, 수은, 카드뮴, 크로뮴 및 총브로민의 스크리닝 | K23: 50 mg/kg 이상 | L23: 신규 | M23: 2013 | N23: KS C IEC 62321-3-1:2013 | O23: Determination of certain substances in electrotechnical products - Part 3-1: Screening - Lead, mercury, cadmium, total chromium and total bromine using X-ray fluorescence spectrometry | P23: 50 mg/kg or more | Q23: N | R23: 소재지
A24: 6 | B24: 02 | C24: 화학시험 | D24: 025 | E24: 실내 및 기타환경 | F24: 실내 및 기타환경 | G24: Indoor and other environments | H24: KS | I24: KS C IEC 62321-5:2013 | J24: 전기전자 제품에서 특정물질의 정량 - 제 5부 : AAS, AFS, ICP-OES 또는 ICP-MS에 의한 폴리머와 전기전자 부품에서 카드뮴과 납 및 크로뮴의 분석과 금속에서 카드뮴과 납의 분석 ( AAS, AFS, ICP-MS 제외) | K24: Pb : 5 mg/kg 이상 Cd : 5 mg/kg 이상 Cr : 5 mg/kg 이상 | L24: 신규 | M24: 2013 | N24: KS C IEC 62321-5:2013 | O24: Determination of certain substances in electrotechnical products - Part 5 : Cadmium, lead and chromium in polymers and electronics and cadmium and lead in metals by AAS, AFS, ICP-OES and ICP-MS (Except : AAS, AFS and ICP-MS) | P24: Pb : 5 mg/kg or more Cd : 5 mg/kg or more Cr : 5 mg/kg or more | Q24: N | R24: 소재지
A25: 7 | B25: 02 | C25: 화학시험 | D25: 025 | E25: 실내 및 기타환경 | F25: 실내 및 기타환경 | G25: Indoor and other environments | H25: KS | I25: KS L 2019:2015 | J25: 유리 중의 6가 크로뮴 정량 방법 | K25: 6가 크로뮴: 1 mg/kg 이상 | L25: 신규 | M25: 2019 | N25: KS L 2019:2015 | O25: Glass — Determination of hexavalent chromium | P25: hexavalent chromium: 1 mg/kg or more | Q25: N | R25: 소재지

Sheet 01.007
A1: 회사/기관명 | B1: 성명 | C1: 평가사구분 | D1: 유효기간 | E1: 최근 평가 | F1: 평가점수 | G1: 순위 | H1: 비고 | J1: 내부심사 | K1: ='1안'!B4 | L1: ='1안'!C4 | M1: ='1안'!D4 | N1: ='1안'!E4 | O1: ='1안'!F4 | P1: ='1안'!G4 | Q1: ='1안'!H4 | R1: ='1안'!I4 | ... Z1: ='1안'!Q4
A2: (주)케이씨티시험연구원 | B2: 박준형 | C2: 평가사 | D2: 2024-07-18 ~ 2027-07-17 | E2: 2026-04-06 ~ 2026-04-07 | J2: 컨설팅 | K2: ='1안'!B5 | L2: ='1안'!C5 | M2: ='1안'!D5 | N2: ='1안'!E5 | O2: ='1안'!F5 | P2: ='1안'!G5 | Q2: ='1안'!H5 | R2: ='1안'!I5 | ... Z2: ='1안'!Q5
A3: (재)한국화학융합시험연구원 | B3: 김선 | C3: 평가사보 | D3: 2024-07-18 ~ 2027-07-17 | E3: 2025-05-21 ~ 2025-05-23 | J3: 직전심사 | K3: ='1안'!B6 | L3: ='1안'!C6 | M3: ='1안'!D6 | N3: ='1안'!E6 | O3: ='1안'!F6 | P3: ='1안'!G6 | Q3: ='1안'!H6 | R3: ='1안'!I6 | ... Z3: ='1안'!Q6
A4: 유한책임회사 한국에너지시험원 | B4: 이해길 | C4: 평가사보 | D4: 2024-06-03 ~ 2027-06-02 | E4: 2025-03-12 ~ 2025-03-13
A5: 재단법인 한국화학융합시험연구원 | B5: 손승환 | C5: 평가사 | D5: 2024-03-19 ~ 2027-03-18 | E5: 2026-04-28 ~ 2026-04-29
A6: 한국건설생활환경시험연구원 | B6: 임순현 | C6: 평가사보 | D6: 2023-12-07 ~ 2026-12-06 | E6: 2025-04-09 ~ 2025-04-11
A7: (주)한국방재기술시험원 | B7: 김태화 | C7: 평가사 | D7: 2023-08-22 ~ 2026-08-21 | E7: 2026-04-16 ~ 2026-04-17
A8: 한국화학융합시험연구원 | B8: 김기웅 | C8: 평가사보 | D8: 2022-10-12 ~ 2025-10-11 | E8: 2024-09-30 ~ 2024-10-02
A9: 한국화학융합시험연구원 | B9: 조홍렬 | C9: 평가사보 | D9: 2022-08-16 ~ 2025-08-15 | E9: 2025-06-11 ~ 2025-06-13
A10: 한국산업기술시험원 | B10: 김용남 | C10: 평가사보 | D10: 2023-02-23 ~ 2026-02-22 | E10: 2025-07-24 ~ 2025-07-25
A11: 한국화학융합시험연구원 | B11: 최준호 | C11: 평가사보 | D11: 2025-10-13 ~ 2028-10-12 | E11: 2025-11-26 ~ 2025-11-28
A12: 주식회사 바이솔라 | B12: 이호열 | C12: 평가사 | D12: 2023-12-21 ~ 2026-12-20 | E12: 2026-02-09 ~ 2026-02-11
A13: 한국건설기술연구원 | B13: 최경석 | C13: 평가사보 | D13: 2017-12-15 ~ 2020-12-14 | E13: 2018-10-24 ~ 2018-10-26
A14: (재)FITI시험연구원 | B14: 조한성 | C14: 평가사 | D14: 2026-03-09 ~ 2029-03-08 | E14: 2026-02-09 ~ 2026-02-11
A15: (주)한국필터시험원 | B15: 이상준 | C15: 평가사보 | D15: 2024-08-09 ~ 2027-08-08 | E15: 2020-11-03 ~ 2020-11-04
... A27: 한국건설생활환경시험연구원 | B27: 유덕룡 | C27: 평가사보 | D27: 2024-08-22 ~ 2027-08-21 | E27: 2026-04-06 ~ 2026-04-07
A28: 한국건설생활환경시험연구원 | B28: 김영근 | C28: 평가사보 | D28: 2006-03-02 ~ 2011-03-01
A29: 한국건설기술연구원 | B29: 여인환 | C29: 평가사보 | D29: 2008-09-02 ~ 2011-09-01
A30: 한국표준협회 | B30: 백영봉 | C30: 평가사 | D30: 2015-07-17 ~ 2018-07-16 | E30: 2017-12-18 ~ 2018-01-19
A31: 태영기술경영연구원 | B31: 정호곤 | C31: 평가사 | D31: 2019-06-11 ~ 2022-06-30 | E31: 2020-06-09 ~ 2020-06-10
A32: 한국화학융합시험연구원 | B32: 박언규 | C32: 평가사보 | D32: 2008-07-18 ~ 2013-07-19 | E32: 2012-12-10 ~ 2012-12-11
A33: 한국화학시험연구원 | B33: 허영태 | C33: 평가사보
A34: 한국화학융합시험연구원 | B34: 방양석 | C34: 선임평가사 | D34: 2006-11-22 ~ 2011-11-21 | E34: 2011-10-12 ~ 2011-10-14

Sheet 01.010
A1: 회사/기관명 | B1: 성명 | C1: 평가사구분 | D1: 유효기간 | E1: 최근 평가 | F1: 평가점수 | G1: 순위 | H1: 비고 | J1: 내부심사 | K1: ='1안'!B4 | L1: ='1안'!C4 | M1: ='1안'!D4 | N1: ='1안'!E4 | O1: ='1안'!F4 | P1: ='1안'!G4 | Q1: ='1안'!H4 | R1: ='1안'!I4 | ... Z1: ='1안'!Q4
A2: (주)건설재료시험연구소 | B2: 윤창수 | C2: 평가사보 | D2: 2025-08-26 ~ 2028-08-25 | E2: 2026-04-29 ~ 2026-04-30
A3: (주)케이씨티시험연구원 | B3: 박준형 | C3: 평가사 | D3: 2024-07-18 ~ 2027-07-17 | E3: 2026-04-06 ~ 2026-04-07
A4: (재)한국화학융합시험연구원 | B4: 김선 | C4: 평가사보 | D4: 2024-07-18 ~ 2027-07-17 | E4: 2025-05-21 ~ 2025-05-23
A5: 한국섬유개발연구원 | B5: 김정완 | C5: 평가사보 | D5: 2024-06-27 ~ 2027-06-26 | E5: 2026-02-04 ~ 2026-02-06
A6: 엘엑스하우시스 | B6: 김은경 | C6: 평가사 | D6: 2024-06-27 ~ 2027-06-26 | E6: 2026-03-09 ~ 2026-03-11
A7: 항공안전기술원 | B7: 양용만 | C7: 평가사보 | D7: 2023-12-07 ~ 2026-12-06
A8: (사)KOTITI시험연구원 | B8: 조진협 | C8: 평가사보 | D8: 2024-01-24 ~ 2027-01-23 | E8: 2026-03-04 ~ 2026-03-05
A9: (주)트리마란 | B9: 권정휘 | C9: 평가사 | D9: 2023-12-21 ~ 2026-12-20 | E9: 2026-02-12 ~ 2026-02-13
A10: 한국인터텍테스팅서비스(주) | B10: 선유성 | C10: 평가사보 | D10: 2023-03-22 ~ 2026-03-21 | E10: 2025-04-09 ~ 2025-04-11
A11: 강원대학교 | B11: 김기세 | C11: 평가사보 | D11: 2023-01-19 ~ 2026-01-18 | E11: 2025-12-17 ~ 2025-12-19
A12: 한국화학융합시험연구원 | B12: 조홍렬 | C12: 평가사보 | D12: 2022-08-16 ~ 2025-08-15 | E12: 2025-06-11 ~ 2025-06-13
A13: (재)한국화학융합시험연구원 | B13: 이주희 | C13: 평가사 | D13: 2022-08-16 ~ 2025-08-15 | E13: 2025-01-06 ~ 2025-01-08
A14: 엘아이지넥스원 주식회사 | B14: 권오현 | C14: 평가사 | D14: 2025-06-30 ~ 2028-06-29 | E14: 2025-12-09 ~ 2025-12-10
A15: 한국화학융합시험연구원 | B15: 김용수 | C15: 평가사보 | D15: 2025-04-22 ~ 2028-04-21 | E15: 2026-02-23 ~ 2026-02-25
A16: FITI시험연구원 | B16: 원경식 | C16: 평가사보 | D16: 2025-03-11 ~ 2028-03-10 | E16: 2025-12-09 ~ 2025-12-11
A17: 한국화학융합시험연구원 | B17: 최준호 | C17: 평가사보 | D17: 2025-10-13 ~ 2028-10-12 | E17: 2025-11-26 ~ 2025-11-28
A18: 국방과학연구소 | B18: 김진성 | C18: 평가사 | D18: 2024-03-19 ~ 2027-03-18 | E18: 2024-10-28 ~ 2024-10-29
A19: 국세청 | B19: 정창우 | C19: 평가사보 | D19: 2023-12-21 ~ 2026-12-20 | E19: 2025-11-17 ~ 2025-11-18
... A48: LIG넥스원(주) | B48: 이진호 | C48: 평가사 | D48: 2025-12-18 ~ 2028-12-17 | E48: 2025-02-10 ~ 2025-02-12
A49: 한국화학융합시험연구원 | B49: 박길종 | C49: 평가사 | D49: 2013-04-05 ~ 2016-04-04
A50: 방위사업청 | B50: 길태준 | C50: 평가사 | D50: 2024-11-13 ~ 2027-11-12 | E50: 2026-04-28 ~ 2026-04-29
A51: 국가기술표준원 | B51: 최철호 | C51: 평가사 | D51: 2015-02-16 ~ 2018-02-15 | E51: 2012-07-12 ~ 2012-07-14
A52: 한국표준협회 | B52: 김상진 | C52: 평가사 | D52: 2025-04-02 ~ 2028-04-01 | E52: 2026-03-11 ~ 2026-03-12
A53: 한국화학융합시험연구원 | B53: 이하형 | C53: 평가사 | D53: 2011-11-15 ~ 2014-11-14 | E53: 2014-10-23 ~ 2014-10-24
A54: 공진기표회 | B54: 정장현 | C54: 평가사 | D54: 2021-02-04 ~ 2024-02-03 | E54: 2022-10-18 ~ 2022-10-20
A55: (재)FITI시험연구원 | B55: 김정효 | C55: 선임평가사 | D55: 2026-02-13 ~ 2029-02-12 | E55: 2026-02-23 ~ 2026-02-25
A56: 메이저위드(주) | B56: 신문기 | C56: 평가사보 | D56: 2011-04-14 ~ 2014-04-13 | E56: 2012-11-27 ~ 2012-11-28
A57: 한국건설생활환경시험연구원 | B57: 신동기 | C57: 평가사 | D57: 2024-10-30 ~ 2027-10-29 | E57: 2025-05-21 ~ 2025-05-23
A58: 한국세라믹기술원 | B58: 김만태 | C58: 평가사 | D58: 2023-08-09 ~ 2026-08-08 | E58: 2025-06-18 ~ 2025-06-20
A59: (재)한국인정지원센터 | B59: 조기성 | C59: 평가사보 | D59: 2011-06-01 ~ 2014-05-31 | E59: 2013-12-05 ~ 2013-12-06
A60: 한밭대학교 산학협력단 | B60: 김익식 | C60: 평가사 | D60: 2025-10-13 ~ 2028-10-12 | E60: 2026-02-09 ~ 2026-02-11
A61: 한국화학융합시험연구원 | B61: 우상윤 | C61: 평가사 | D61: 2010-11-05 ~ 2013-11-04 | E61: 2013-06-26 ~ 2013-06-28
... A82: 한국화학융합시험연구원 | B82: 김덕훈 | C82: 평가사 | D82: 2024-11-13 ~ 2027-11-12 | E82: 2026-04-29 ~ 2026-04-30
A83: 한국화학시험연구원 | B83: 문영범
A84: 한국건설생활환경시험연구원 | B84: 황원구 | C84: 평가사보 | D84: 2009-02-19 ~ 2012-02-18 | E84: 2010-09-01 ~ 2010-09-03
A85: 한국건설생활환경시험연구원 | B85: 이송원 | C85: 평가사 | D85: 2021-01-11 ~ 2024-01-10 | E85: 2020-03-18 ~ 2020-03-20
A86: 한국화학시험연구원 | B86: 김복기 | C86: 평가사보 | D86: 2004-05-21 ~ 2009-05-20 | E86: 2009-06-24 ~ 2009-06-26
A87: LS전선 | B87: 신은미 | C87: 평가사보 | D87: 2009-02-19 ~ 2012-02-18 | E87: 2010-11-08 ~ 2010-11-10
A88: 삼우티씨씨 연구소 | B88: 박상순 | C88: 평가사 | D88: 2023-10-25 ~ 2026-10-24 | E88: 2026-04-20 ~ 2026-04-21
...

Sheet 02.025
A1: 회사/기관명 | B1: 성명 | C1: 평가사구분 | D1: 유효기간 | E1: 최근 평가 | F1: 평가점수 | G1: 순위 | H1: 비고 | J1: 내부심사 | K1: ='1안'!B4 | L1: ='1안'!C4 | M1: ='1안'!D4 | N1: ='1안'!E4 | O1: ='1안'!F4 | P1: ='1안'!G4 | Q1: ='1안'!H4 | R1: ='1안'!I4 | ... Z1: ='1안'!Q4
A2: KATRI시험연구원 | B2: 윤형준 | C2: 평가사보 | D2: 2026-02-13 ~ 2029-02-12
A3: 에스지생활안전 주식회사 | B3: 이재인 | C3: 평가사보 | D3: 2024-08-09 ~ 2027-08-08 | E3: 2025-11-19 ~ 2025-11-21
A4: 엘엑스하우시스 | B4: 김은경 | C4: 평가사 | D4: 2024-06-27 ~ 2027-06-26 | E4: 2026-03-09 ~ 2026-03-11
A5: 재단법인 한국화학융합시험연구원 | B5: 손승환 | C5: 평가사 | D5: 2024-03-19 ~ 2027-03-18 | E5: 2026-04-28 ~ 2026-04-29
A6: (주)한국품질시험원 | B6: 이보영 | C6: 평가사보 | D6: 2023-12-21 ~ 2026-12-20 | E6: 2025-02-26 ~ 2025-02-27
A7: 한국산업기술시험원 | B7: 이원주 | C7: 평가사보 | D7: 2023-11-08 ~ 2026-11-07 | E7: 2026-01-20 ~ 2026-01-21
A8: (재)한국건설생활환경시험연구원 | B8: 이용성 | C8: 평가사보 | D8: 2024-04-16 ~ 2027-04-15 | E8: 2026-02-03 ~ 2026-02-05
A9: (사)KOTITI시험연구원 | B9: 류건영 | C9: 평가사보 | D9: 2023-08-09 ~ 2026-08-08 | E9: 2026-03-09 ~ 2026-03-11
A10: (재)세종테크노파크 | B10: 신윤학 | C10: 평가사 | D10: 2024-11-13 ~ 2027-11-12 | E10: 2026-04-07 ~ 2026-04-08
A11: 삼성전자 | B11: 이종한 | C11: 평가사보 | D11: 2023-05-03 ~ 2026-05-02 | E11: 2025-11-12 ~ 2025-11-14
A12: (주)케이씨씨 중앙연구소 | B12: 서우교 | C12: 평가사보 | D12: 2026-03-09 ~ 2029-03-08 | E12: 2024-08-27 ~ 2024-08-28
A13: KOTITI 시험연구원 | B13: 김재우 | C13: 평가사보 | D13: 2023-11-08 ~ 2026-11-07 | E13: 2026-04-02 ~ 2026-04-03
A14: (재)KATRI시험연구원 | B14: 장윤희 | C14: 평가사보 | D14: 2023-04-05 ~ 2026-04-04
A15: 한국건설생활환경시험연구원 | B15: 이세진 | C15: 평가사보 | D15: 2023-06-14 ~ 2026-06-13 | E15: 2026-01-13 ~ 2026-01-14
A16: (주)한국이엠씨 | B16: 신진호 | C16: 평가사보 | D16: 2025-11-12 ~ 2028-11-11 | E16: 2026-04-08 ~ 2026-04-10
A17: 조달청 조달품질원 | B17: 한홍환 | C17: 평가사 | D17: 2026-02-13 ~ 2029-02-12 | E17: 2025-12-22 ~ 2025-12-23
A18: 한국화학융합시험연구원 | B18: 이정희 | C18: 평가사보 | D18: 2023-04-05 ~ 2026-04-04 | E18: 2025-01-20 ~ 2025-01-22
A19: (재)한국화학융합시험연구원 | B19: 유태규 | C19: 평가사보 | D19: 2023-02-23 ~ 2026-02-22 | E19: 2025-06-18 ~ 2025-06-20
A20: 조광페인트 | B20: 오민경 | C20: 평가사보 | D20: 2025-12-18 ~ 2028-12-17 | E20: 2026-01-13 ~ 2026-01-14
A21: 강원대학교 | B21: 김기세 | C21: 평가사보 | D21: 2023-01-19 ~ 2026-01-18 | E21: 2025-12-17 ~ 2025-12-19
A22: (재)한국환경수도연구원 | B22: 김동훈 | C22: 평가사보 | D22: 2026-02-13 ~ 2029-02-12 | E22: 2024-09-23 ~ 2024-09-25
A23: (재)한국화학융합시험연구원 | B23: 장순복 | C23: 평가사보 | D23: 2022-11-09 ~ 2025-11-08 | E23: 2025-08-25 ~ 2025-08-27
A24: (재)한국화학융합시험연구원 | B24: 홍주은 | C24: 평가사보 | D24: 2024-06-03 ~ 2027-06-02 | E24: 2026-04-14 ~ 2026-04-15
A25: (재)한국화학융합시험연구원 | B25: 이헌재 | C25: 평가사 | D25: 2025-11-28 ~ 2028-11-27 | E25: 2026-01-12 ~ 2026-01-13
A26: 한국화학융합시험연구원 | B26: 정정설 | C26: 평가사보 | D26: 2025-11-12 ~ 2028-11-11 | E26: 2025-06-25 ~ 2025-06-27
A27: 한국건설생활환경시험연구원 | B27: 김택수 | C27: 평가사보 | D27: 2023-06-14 ~ 2026-06-13
A28: 한국산업기술시험원 | B28: 홍길환 | C28: 평가사보 | D28: 2022-02-21 ~ 2025-02-20 | E28: 2024-11-25 ~ 2024-11-26
A29: (주)신비기술개발 | B29: 김숙동 | C29: 평가사보 | D29: 2022-01-28 ~ 2025-01-27 | E29: 2024-05-09 ~ 2024-05-11
A30: 원진재단부설 노동환경건강연구소 | B30: 조영환 | C30: 평가사보 | D30: 2024-08-09 ~ 2027-08-08 | E30: 2026-04-14 ~ 2026-04-16
A31: (재)한국건설생활환경시험연구원 | B31: 서영민 | C31: 평가사 | D31: 2025-07-18 ~ 2028-07-17 | E31: 2026-02-09 ~ 2026-02-11
A32: (재)KATRI시험연구원 | B32: 신은호 | C32: 평가사 | D32: 2025-08-26 ~ 2028-08-25 | E32: 2025-11-26 ~ 2025-11-28
A33: 조달청 조달품질원 | B33: 문윤정 | C33: 평가사보 | D33: 2025-04-22 ~ 2028-04-21 | E33: 2025-12-23 ~ 2025-12-24
A34: 한국실내건축환경시험연구원 | B34: 박준형 | C34: 평가사보 | D34: 2024-06-27 ~ 2027-06-26 | E34: 2026-03-05 ~ 2026-03-06
A35: (재)FITI시험연구원 | B35: 박상준 | C35: 평가사 | D35: 2024-10-16 ~ 2027-10-15 | E35: 2025-03-19 ~ 2025-03-20
A36: (주) 엘엑스하우시스 | B36: 고재윤 | C36: 평가사 | D36: 2024-05-09 ~ 2027-05-08 | E36: 2026-03-05 ~ 2026-03-06
A37: KOTITI 시험연구원 | B37: 김민섭 | C37: 평가사 | D37: 2024-04-16 ~ 2027-04-15 | E37: 2026-01-28 ~ 2026-01-30
A38: 한국에스지에스(주) | B38: 정양선 | C38: 평가사보 | D38: 2026-02-13 ~ 2029-02-12 | E38: 2026-04-07 ~ 2026-04-08
A39: 한국토지주택공사 | B39: 황종규 | C39: 평가사보 | D39: 2021-03-02 ~ 2024-03-01
A40: 한국세라믹기술원 | B40: 이명규 | C40: 평가사 | D40: 2023-11-08 ~ 2026-11-07 | E40: 2026-02-09 ~ 2026-02-11
...
